Workbook

Sheet 가이드위반
B2: ■홈페이지 RS 요금제 가이드 위반 | K2: 1. 홈페이지 Sheet M열이 RS인 요금제 & 2. 홈페이지 sheet F열이 LGU+ or LG U+ & 3. 홈페이지 sheet I열이 6 이하
B3: 순번 | C3: 사업자 | D3: 요금제 명 | E3: 월 요금 | F3: 할인 기간 | G3: 기간 이 후 요금
B18: ■홈페이지 RM 요금제 가이드 위반 | K18: 1. 홈페이지 Sheet M열이 RS가 아닌 요금제 & 2. 홈페이지 sheet F열이 LGU+ or LG U+ & 3. 홈페이지 sheet I열이 5 이하 또는 1. 홈페이지 Sheet M열이 RS가 아닌 요금제 & 2. 홈페이지 sheet F열이 LGU+ or LG U+ & 3. 홈페이지 sheet H열이 0
B19: 순번 | C19: 사업자 | D19: 요금제 명 | E19: 월 요금 | F19: 할인 기간 | G19: 기간 이 후 요금

Sheet 홈페이지
A1: 사업자 | B1: 요금제 | C1: 통화 제공량 | D1: 문자 제공량 | E1: 데이터 제공량 | F1: 망구분 | G1: LTE/5G 구분 | H1: 월 요금 | I1: 할인 기간 | J1: 기간 이후 요금 | K1: 요금구분 | L1: 홈페이지 | M1: RS구분 | N1: 가이드위반
A2: 프리티 | B2: 더든든한안심15G+1M | C2: 300분 | D2: 300건 | E2: 15GB | F2: LGU+ | G2: 5G | H2: 110 | I2: 6 | J2: 36300 | K2: 후불 | L2: 홈페이지 | M2: =IFERROR(VLOOKUP($C2&$D2&$E2,참조!$B:$G,6,0),"")
A3: 프리티 | B3: (5G)더든든한200분20G | C3: 200분 | D3: 100건 | E3: 20GB | F3: KT | G3: 5G | H3: 5500 | K3: 후불 | L3: 홈페이지 | M3: =IFERROR(VLOOKUP($C3&$D3&$E3,참조!$B:$G,6,0),"")
A4: 프리티 | B4: 더든든한200분20G | C4: 200분 | D4: 100건 | E4: 20GB | F4: KT | G4: LTE | H4: 10 | I4: 7 | J4: 22000 | K4: 후불 | L4: 홈페이지 | M4: =IFERROR(VLOOKUP($C4&$D4&$E4,참조!$B:$G,6,0),"")
A5: 프리티 | B5: 더든든한500분20G | C5: 500분 | D5: 100건 | E5: 20GB | F5: KT | G5: LTE | H5: 10 | I5: 10 | J5: 24200 | K5: 후불 | L5: 홈페이지 | M5: =IFERROR(VLOOKUP($C5&$D5&$E5,참조!$B:$G,6,0),"")
A6: 프리티 | B6: 더든든한200분15G | C6: 200분 | D6: 100건 | E6: 15GB | F6: KT | G6: 5G | H6: 10 | I6: 7 | J6: 19800 | K6: 후불 | L6: 홈페이지 | M6: =IFERROR(VLOOKUP($C6&$D6&$E6,참조!$B:$G,6,0),"")
A7: 프리티 | B7: 더든든한200분15G | C7: 200분 | D7: 100건 | E7: 15GB | F7: SKT | G7: 5G | H7: 10 | I7: 7 | J7: 27800 | K7: 후불 | L7: 홈페이지 | M7: =IFERROR(VLOOKUP($C7&$D7&$E7,참조!$B:$G,6,0),"")
A8: 프리티 | B8: 음성기본데이터10G | C8: 기본제공 | D8: 기본제공 | E8: 10GB | F8: SKT | G8: LTE | H8: 10 | I8: 10 | J8: 23100 | K8: 후불 | L8: 홈페이지 | M8: =IFERROR(VLOOKUP($C8&$D8&$E8,참조!$B:$G,6,0),"")
A9: 프리티 | B9: 데이터안심4.5G+1Mbps | C9: 기본제공 | D9: 기본제공 | E9: 4.5GB | F9: LGU+ | G9: 5G | H9: 990 | I9: 7 | J9: 23100 | K9: 후불 | L9: 홈페이지 | M9: =IFERROR(VLOOKUP($C9&$D9&$E9,참조!$B:$G,6,0),"")
A10: 프리티 | B10: 5G 든든한200분10G | C10: 200분 | D10: 200건 | E10: 10GB | F10: KT | G10: 5G | H10: 10 | I10: 10 | J10: 5500 | K10: 후불 | L10: 홈페이지 | M10: =IFERROR(VLOOKUP($C10&$D10&$E10,참조!$B:$G,6,0),"")
A11: 프리티 | B11: 데이터안심10G | C11: 기본제공 | D11: 300건 | E11: 10GB | F11: KT | G11: LTE | H11: 10 | I11: 7 | J11: 12100 | K11: 후불 | L11: 홈페이지 | M11: =IFERROR(VLOOKUP($C11&$D11&$E11,참조!$B:$G,6,0),"")
A12: 프리티 | B12: 든든한350분5G | C12: 350분 | D12: 100건 | E12: 5GB | F12: SKT | G12: 5G | H12: 10 | I12: 12 | J12: 7700 | K12: 후불 | L12: 홈페이지 | M12: =IFERROR(VLOOKUP($C12&$D12&$E12,참조!$B:$G,6,0),"")
A13: 프리티 | B13: 든든한 350분5G | C13: 350분 | D13: 100건 | E13: 5GB | F13: LGU+ | G13: 5G | H13: 110 | I13: 10 | J13: 7700 | K13: 후불 | L13: 홈페이지 | M13: =IFERROR(VLOOKUP($C13&$D13&$E13,참조!$B:$G,6,0),"")
A14: 프리티 | B14: 든든한 200분6G | C14: 200분 | D14: 100건 | E14: 6GB | F14: SKT | G14: LTE | H14: 10 | I14: 10 | J14: 4510 | K14: 후불 | L14: 홈페이지 | M14: =IFERROR(VLOOKUP($C14&$D14&$E14,참조!$B:$G,6,0),"")
A15: 프리티 | B15: 든든한 300분10G | C15: 300분 | D15: 300건 | E15: 10GB | F15: SKT | G15: LTE | H15: 34100 | K15: 후불 | L15: 홈페이지 | M15: =IFERROR(VLOOKUP($C15&$D15&$E15,참조!$B:$G,6,0),"")
A16: 프리티 | B16: 데이터팡팡매일5G+ | C16: 기본제공 | D16: 기본제공 | E16: 매일5GB | F16: LGU+ | G16: 5G | H16: 13430 | I16: 7 | J16: 52700 | K16: 후불 | L16: 홈페이지 | M16: =IFERROR(VLOOKUP($C16&$D16&$E16,참조!$B:$G,6,0),"") -> RS
A17: 프리티 | B17: 월간Pick 100G+ | C17: 기본제공 | D17: 기본제공 | E17: 100GB | F17: SKT | G17: LTE | H17: 18700 | I17: 7 | J17: 56760 | K17: 후불 | L17: 홈페이지 | M17: =IFERROR(VLOOKUP($C17&$D17&$E17,참조!$B:$G,6,0),"") -> RS
A18: 프리티 | B18: 월간Pick 11G+ | C18: 기본제공 | D18: 기본제공 | E18: 11GB+매일2GB | F18: SKT | G18: LTE | H18: 15070 | I18: 7 | J18: 48730 | K18: 후불 | L18: 홈페이지 | M18: =IFERROR(VLOOKUP($C18&$D18&$E18,참조!$B:$G,6,0),"") -> RS
A19: 프리티 | B19: 월간Pick 15G+ | C19: 100분 | D19: 100건 | E19: 15GB | F19: SKT | G19: 5G | H19: 14740 | I19: 7 | J19: 36740 | K19: 후불 | L19: 홈페이지 | M19: =IFERROR(VLOOKUP($C19&$D19&$E19,참조!$B:$G,6,0),"") -> RS
A20: 프리티 | B20: 월간Pick 7G+1M | C20: 기본제공 | D20: 기본제공 | E20: 7GB | F20: SKT | G20: LTE | H20: 11000 | I20: 7 | J20: 29040 | K20: 후불 | L20: 홈페이지 | M20: =IFERROR(VLOOKUP($C20&$D20&$E20,참조!$B:$G,6,0),"") -> RS
A21: 프리티 | B21: 하나은행 500분20G | C21: 500분 | D21: 100건 | E21: 20GB | F21: SKT | G21: LTE | H21: 4510 | I21: 12 | J21: 20900 | K21: 후불 | L21: 홈페이지 | M21: =IFERROR(VLOOKUP($C21&$D21&$E21,참조!$B:$G,6,0),"")
A22: 프리티 | B22: 하나은행 200분15G | C22: 200분 | D22: 100건 | E22: 15GB | F22: SKT | G22: 5G | H22: 1100 | I22: 12 | J22: 17600 | K22: 후불 | L22: 홈페이지 | M22: =IFERROR(VLOOKUP($C22&$D22&$E22,참조!$B:$G,6,0),"")
A23: 프리티 | B23: 프리티 편의점금액권 5000 150G+ | C23: 기본제공 | D23: 기본제공 | E23: 150GB | F23: LGU+ | G23: 5G | H23: 29920 | I23: 24 | J23: 62700 | K23: 후불 | L23: 홈페이지 | M23: =IFERROR(VLOOKUP($C23&$D23&$E23,참조!$B:$G,6,0),"") -> RS
A24: 프리티 | B24: 프리티 편의점금액권 100G+ | C24: 기본제공 | D24: 기본제공 | E24: 100GB | F24: SKT | G24: LTE | H24: 18700 | I24: 7 | J24: 57310 | K24: 후불 | L24: 홈페이지 | M24: =IFERROR(VLOOKUP($C24&$D24&$E24,참조!$B:$G,6,0),"") -> RS
A25: 프리티 | B25: 프리티 편의점금액권 11G+ | C25: 기본제공 | D25: 기본제공 | E25: 11GB+매일2GB | F25: SKT | G25: LTE | H25: 15070 | I25: 7 | J25: 49280 | K25: 후불 | L25: 홈페이지 | M25: =IFERROR(VLOOKUP($C25&$D25&$E25,참조!$B:$G,6,0),"") -> RS
A26: 프리티 | B26: 프리티 편의점금액권 15G+ | C26: 100분 | D26: 100건 | E26: 15GB | F26: SKT | G26: 5G | H26: 14740 | I26: 7 | J26: 37290 | K26: 후불 | L26: 홈페이지 | M26: =IFERROR(VLOOKUP($C26&$D26&$E26,참조!$B:$G,6,0),"") -> RS
A27: 프리티 | B27: 프리티 편의점금액권 7G+1M | C27: 기본제공 | D27: 기본제공 | E27: 7GB | F27: SKT | G27: LTE | H27: 11000 | I27: 7 | J27: 29590 | K27: 후불 | L27: 홈페이지 | M27: =IFERROR(VLOOKUP($C27&$D27&$E27,참조!$B:$G,6,0),"") -> RS
... A29: 프리티 | B29: 쿠팡캐시 7G+1M | C29: 기본제공 | D29: 기본제공 | E29: 7GB+추가10GB | F29: KT | G29: LTE | H29: 9900 | I29: 7 | J29: 27500 | K29: 후불 | L29: 홈페이지 | M29: =IFERROR(VLOOKUP($C29&$D29&$E29,참조!$B:$G,6,0),"") -> RS
A30: 프리티 | B30: 프리티구독7G+(대한항공 기프트카드) | C30: 기본제공 | D30: 기본제공 | E30: 7GB | F30: LGU+ | G30: LTE | H30: 17600 | K30: 후불 | L30: 홈페이지 | M30: =IFERROR(VLOOKUP($C30&$D30&$E30,참조!$B:$G,6,0),"") -> RS
A31: 프리티 | B31: 프리티구독7G+1M(대한항공 기프트카드) | C31: 기본제공 | D31: 기본제공 | E31: 7GB | F31: SKT | G31: LTE | H31: 17600 | K31: 후불 | L31: 홈페이지 | M31: =IFERROR(VLOOKUP($C31&$D31&$E31,참조!$B:$G,6,0),"") -> RS
A32: 프리티 | B32: 더든든한500분30G | C32: 500분 | D32: 100건 | E32: 30GB | F32: SKT | G32: LTE | H32: 12100 | K32: 후불 | L32: 홈페이지 | M32: =IFERROR(VLOOKUP($C32&$D32&$E32,참조!$B:$G,6,0),"")
A33: 프리티 | B33: CGV 1+1 100G+ | C33: 기본제공 | D33: 기본제공 | E33: 100GB | F33: KT | G33: LTE | H33: 20900 | I33: 7 | J33: 59840 | K33: 후불 | L33: 홈페이지 | M33: =IFERROR(VLOOKUP($C33&$D33&$E33,참조!$B:$G,6,0),"") -> RS
A34: 프리티 | B34: NH프리덤100G+5M | C34: 기본제공 | D34: 기본제공 | E34: 100GB | F34: SKT | G34: LTE | H34: 24200 | I34: 7 | J34: 55000 | K34: 후불 | L34: 홈페이지 | M34: =IFERROR(VLOOKUP($C34&$D34&$E34,참조!$B:$G,6,0),"") -> RS
A35: 프리티 | B35: 다이소 100G+ | C35: 기본제공 | D35: 기본제공 | E35: 100GB | F35: KT | G35: LTE | H35: 19800 | I35: 7 | J35: 55000 | K35: 후불 | L35: 홈페이지 | M35: =IFERROR(VLOOKUP($C35&$D35&$E35,참조!$B:$G,6,0),"") -> RS
A36: 프리티 | B36: 다이소 7G+1M | C36: 기본제공 | D36: 기본제공 | E36: 7GB+추가10GB | F36: KT | G36: LTE | H36: 9900 | I36: 7 | J36: 27500 | K36: 후불 | L36: 홈페이지 | M36: =IFERROR(VLOOKUP($C36&$D36&$E36,참조!$B:$G,6,0),"") -> RS
A37: 프리티 | B37: CGV 1+1쿠폰 100G+ | C37: 기본제공 | D37: 기본제공 | E37: 100GB | F37: SKT | G37: LTE | H37: 16500 | I37: 7 | J37: 59950 | K37: 후불 | L37: 홈페이지 | M37: =IFERROR(VLOOKUP($C37&$D37&$E37,참조!$B:$G,6,0),"") -> RS
A38: 프리티 | B38: NH프리덤11G+ | C38: 기본제공 | D38: 기본제공 | E38: 11GB+매일2GB | F38: SKT | G38: LTE | H38: 20900 | I38: 7 | J38: 49390 | K38: 후불 | L38: 홈페이지 | M38: =IFERROR(VLOOKUP($C38&$D38&$E38,참조!$B:$G,6,0),"") -> RS
A39: 프리티 | B39: NH프리덤7G+1M | C39: 기본제공 | D39: 기본제공 | E39: 7GB | F39: SKT | G39: LTE | H39: 12100 | I39: 7 | J39: 29700 | K39: 후불 | L39: 홈페이지 | M39: =IFERROR(VLOOKUP($C39&$D39&$E39,참조!$B:$G,6,0),"") -> RS
A40: 프리티 | B40: (5G)더빠른125G+ | C40: 기본제공 | D40: 기본제공 | E40: 125GB | F40: LGU+ | G40: 5G | H40: 15070 | I40: 7 | J40: 58300 | K40: 후불 | L40: 홈페이지 | M40: =IFERROR(VLOOKUP($C40&$D40&$E40,참조!$B:$G,6,0),"") -> RS
A41: 프리티 | B41: (5G)더든든한200분15G | C41: 200분 | D41: 100건 | E41: 15GB | F41: KT | G41: 5G | H41: 4400 | K41: 후불 | L41: 홈페이지 | M41: =IFERROR(VLOOKUP($C41&$D41&$E41,참조!$B:$G,6,0),"")
...

Sheet 전일 대비 변동
A1: 변동구분 | B1: 사업자 | C1: 요금제 | D1: 망정보 | E1: LTE/5G | F1: 전일 월요금 | G1: 금일 월요금 | H1: 전일 할인기간 | I1: 금일 할인기간 | J1: 전일 이후요금 | K1: 금일 이후요금

Sheet 참조
B2: 통합 | C2: 통화 제공량 | D2: 문자 제공량 | E2: 데이터 제공량
B3: 기본제공기본제공7GB | C3: 기본제공 | D3: 기본제공 | E3: 7GB | F3: 7GB | G3: RS
B4: 기본제공기본제공7GB+추가10GB | C4: 기본제공 | D4: 기본제공 | E4: 7GB+추가10GB | F4: 7GB | G4: RS
B5: 기본제공(부가통화300분)기본제공7GB+10GB(24개월)+1Mbps | C5: 기본제공(부가통화300분) | D5: 기본제공 | E5: 7GB+10GB(24개월)+1Mbps | F5: 7GB | G5: RS
B6: 기본제공기본제공7GB + 1Mbps | C6: 기본제공 | D6: 기본제공 | E6: 7GB + 1Mbps | F6: 7GB | G6: RS
B7: 기본제공기본제공월 7GB (소진시 1Mbps) | C7: 기본제공 | D7: 기본제공 | E7: 월 7GB (소진시 1Mbps) | F7: 7GB | G7: RS
B8: 기본제공기본제공월 37GB (소진시 1Mbps) | C8: 기본제공 | D8: 기본제공 | E8: 월 37GB (소진시 1Mbps) | F8: 7GB | G8: RS
B9: 기본제공기본제공월 7GB (소진시 최대 1Mbps 속도로 무제한 이용) | C9: 기본제공 | D9: 기본제공 | E9: 월 7GB (소진시 최대 1Mbps 속도로 무제한 이용) | F9: 7GB | G9: RS
B10: 기본제공기본제공월 7GB (소진시 1Mbps 속도로 데이터 무제한 사용가능) | C10: 기본제공 | D10: 기본제공 | E10: 월 7GB (소진시 1Mbps 속도로 데이터 무제한 사용가능) | F10: 7GB | G10: RS
B11: 기본제공기본제공월 7GB+ | C11: 기본제공 | D11: 기본제공 | E11: 월 7GB+ | F11: 7GB | G11: RS
B12: 기본제공 + 영상/부가통화 300분기본제공월 7GB + 1Mbps | C12: 기본제공 + 영상/부가통화 300분 | D12: 기본제공 | E12: 월 7GB + 1Mbps | F12: 7GB | G12: RS
B13: 무제한 (부가 음성 300분)무제한월 7GB (소진시 1Mbps) | C13: 무제한 (부가 음성 300분) | D13: 무제한 | E13: 월 7GB (소진시 1Mbps) | F13: 7GB | G13: RS
B14: 기본제공 (부가300분)기본제공월 7GB+1Mbps | C14: 기본제공 (부가300분) | D14: 기본제공 | E14: 월 7GB+1Mbps | F14: 7GB | G14: RS
... B139: 기본제공기본제공월 180GB+10Mbps | C139: 기본제공 | D139: 기본제공 | E139: 월 180GB+10Mbps | F139: 180G | G139: RS
